<?xml version="1.0" encoding="utf-8"?>
<!-- =================================================================================== -->
<!-- |    This document was autogenerated by xacro from main.urdf.xacro                | -->
<!-- |    EDITING THIS FILE BY HAND IS NOT RECOMMENDED                                 | -->
<!-- =================================================================================== -->
<robot name="DIR_model">
  <link name="base_footprint"/>
  <link name="base_link">
    <visual>
      <origin rpy="-1.57 0 1.57" xyz="0.075 -0.325 0.112"/>
      <geometry>
        <mesh filename="package://sick_scan/meshes/base_link.stl"/>
        <scale>0.001 0.001 0.001</scale>
      </geometry>
      <material name="base_material">
        <color rgba="0.098039 0.098039 0.098039 1"/>
      </material>
    </visual>
  </link>
  <joint name="base_joint" type="fixed">
    <parent link="base_footprint"/>
    <child link="base_link"/>
    <origin xyz="0 0 0.02"/>
  </joint>
  <link name="rim_left_link">
    <visual>
      <geometry>
        <mesh filename="package://sick_scan/meshes/demo_rim.stl"/>
      </geometry>
      <material name="rim_left_material">
        <color rgba="0.3 0 0 1"/>
      </material>
    </visual>
  </link>
  <joint name="rim_left_joint" type="continuous">
    <parent link="base_link"/>
    <child link="rim_left_link"/>
    <axis xyz="0 0 1"/>
    <origin rpy="1.570796326794896 0 -0.523599" xyz="-0.03 0.215 0.04"/>
  </joint>
  <link name="rim_back_link">
    <visual>
      <geometry>
        <mesh filename="package://sick_scan/meshes/demo_rim.stl"/>
      </geometry>
      <material name="rim_back_material">
        <color rgba="0.3 0 0 1"/>
      </material>
    </visual>
  </link>
  <joint name="rim_back_joint" type="continuous">
    <parent link="base_link"/>
    <child link="rim_back_link"/>
    <axis xyz="0 0 1"/>
    <origin rpy="1.570796326794896 0 1.5708" xyz="-0.397 0 0.04"/>
  </joint>
  <link name="rim_right_link">
    <visual>
      <geometry>
        <mesh filename="package://sick_scan/meshes/demo_rim.stl"/>
      </geometry>
      <material name="rim_right_material">
        <color rgba="0.3 0 0 1"/>
      </material>
    </visual>
  </link>
  <joint name="rim_right_joint" type="continuous">
    <parent link="base_link"/>
    <child link="rim_right_link"/>
    <axis xyz="0 0 1"/>
    <origin rpy="1.570796326794896 0 -2.61799" xyz="-0.03 -0.208 0.04"/>
  </joint>
  <joint name="sick_joint_R" type="fixed">
    <parent link="base_link"/>
    <child link="sick_R_laser"/>
    <origin rpy="3.1415 0 -1.047" xyz="0.005 -0.275 0.04"/>
  </joint>
  <link name="sick_R_laser">
    <visual>
      <geometry>
        <mesh filename="package://sick_scan/meshes/sick_tim_5xx.stl"/>
      </geometry>
      <material name="blue">
        <color rgba="0 0 1 1"/>
      </material>
    </visual>
  </link>
  <joint name="sick_joint_L" type="fixed">
    <parent link="base_link"/>
    <child link="sick_L_laser"/>
    <origin rpy="3.1415 0 1.047" xyz="0.005 0.275 0.04"/>
  </joint>
  <link name="sick_L_laser">
    <visual>
      <geometry>
        <mesh filename="package://sick_scan/meshes/sick_tim_5xx.stl"/>
      </geometry>
      <material name="blue">
        <color rgba="0 0 1 1"/>
      </material>
    </visual>
  </link>
</robot>
